Workbook

Sheet Workshop #1
B3: Company Background and Industry Analysis
B5: Workshop 1
B6: Mathilde Sison, Averie Forshaw
B7: BUS 438
B8: Prof. Mahdi Rastad
A10: 3 | B10: a | C10: Primary SIC: Courier services and express delivery services
B12: b | C12: UPS runs an integrated delivery and logistics model, earning most of its revenue from domestic and international shipping fees for parcels and freight, priced by speed, distance, weight, and volume. It layers on higher-margin value‑added services including insurance, customs brokerage, supply chain contracts, and e‑commerce logistics.
B14: c(i) | C14: Headquarters: 55 Glenlake Parkway, NE, Atlanta, GA 30328, USA
B16: c(ii) | C16: Subsidaries: US, NAM, Europe, Asia-Pacific, Latin America, Middle East, parts of Africa
B18: c(iii) | C18: UPS operates globally.
B20: d | C20: Number of Employees: 490,000
A22: 4 | B22: a | C22: Most Recent (12/31/24)
C23: Total Assets: 70,070,000
C24: Total Equity: 16,718,000
C25: Total Revenue: 91,070,000
B27: b

Sheet Workshop #2
B3: Financial Statements and Performance Analysis
B5: Workshop 2
B6: Mathilde Sison, Averie Forshaw
B7: BUS 438
B8: Prof. Mahdi Rastad
B11: UPS Current Stock Price: | D11: 108.03
A13: 2 | C13: 2016 | D13: 2017 | E13: 2018 | F13: 2019 | G13: 2020 | H13: 2021 | I13: 2022 | J13: 2023 | K13: 2024 | L13: 2025 | M13: 2026
B14: Average Yearly Share Price | C14: =AVERAGE(Stock!$B111:$B122) -> 106.34167 | D14: =AVERAGE(Stock!B99:B110) -> 112.42333 | E14: =AVERAGE(Stock!B87:B98) -> 112.59333 | F14: =AVERAGE(Stock!B75:B86) -> 111.63833 | G14: =AVERAGE(Stock!B63:B74) -> 130.21417 | H14: =AVERAGE(Stock!B51:B62) -> 192.04333 | I14: =AVERAGE(Stock!B39:B50) -> 187.845 | J14: =AVERAGE(Stock!B27:B38) -> 170.855 | K14: =AVERAGE(Stock!B15:B26) -> 137.76583 | L14: =AVERAGE(Stock!B3:B14) -> 98.796667 | M14: =AVERAGE(Stock!B2) -> 106.58
A17: 3 | B17: a Standardized Annual Income Statement as a % of Total Revenue
E19: 44196 | F19: 44561 | G19: 44926 | H19: 45291 | I19: 45657
B20: Sales | E20: =Financials!B4/Financials!$B$4 -> 1 | F20: =Financials!C4/Financials!$C$4 -> 1 | G20: =Financials!D4/Financials!$D$4 -> 1 | H20: =Financials!E4/Financials!$E$4 -> 1 | I20: =Financials!F4/Financials!$F$4 -> 1
B21: Cost of Goods Sold (COGS) incl. D&A | E21: =Financials!B5/Financials!$B$4 -> 0.7420054 | F21: =Financials!C5/Financials!$C$4 -> 0.82066582 | G21: =Financials!D5/Financials!$D$4 -> 0.79926825 | H21: =Financials!E5/Financials!$E$4 -> 0.80488181 | I21: =Financials!F5/Financials!$F$4 -> 0.81233085
B22: COGS excluding D&A | E22: =Financials!B6/Financials!$B$4 -> 0.71005069 | F22: =Financials!C6/Financials!$C$4 -> 0.79028641 | G22: =Financials!D6/Financials!$D$4 -> 0.76739908 | H22: =Financials!E6/Financials!$E$4 -> 0.76778886 | I22: =Financials!F6/Financials!$F$4 -> 0.77262526
B23: Depreciation & Amortization Expense | E23: =Financials!B7/Financials!$B$4 -> 0.031954709 | F23: =Financials!C7/Financials!$C$4 -> 0.030379408 | G23: =Financials!D7/Financials!$D$4 -> 0.031869164 | H23: =Financials!E7/Financials!$E$4 -> 0.037092953 | I23: =Financials!F7/Financials!$F$4 -> 0.039705591
B24: Depreciation | E24: =Financials!B8/Financials!$B$4 -> 0.027027667 | F24: =Financials!C8/Financials!$C$4 -> 0.025492778 | G24: =Financials!D8/Financials!$D$4 -> 0.026620949 | H24: =Financials!E8/Financials!$E$4 -> 0.030514078 | I24: =Financials!F8/Financials!$F$4 -> 0.032576408
B25: Amortization of Intangibles | E25: =Financials!B9/Financials!$B$4 -> 0.0049270419 | F25: =Financials!C9/Financials!$C$4 -> 0.0048866302 | G25: =Financials!D9/Financials!$D$4 -> 0.0052482156 | H25: =Financials!E9/Financials!$E$4 -> 0.0065788749 | I25: =Financials!F9/Financials!$F$4 -> 0.0071291834
B26: Gross Income | E26: =Financials!B10/Financials!$B$4 -> 0.2579946 | F26: =Financials!C10/Financials!$C$4 -> 0.17933418 | G26: =Financials!D10/Financials!$D$4 -> 0.20073175 | H26: =Financials!E10/Financials!$E$4 -> 0.19511819 | I26: =Financials!F10/Financials!$F$4 -> 0.18766915
B27: SG&A Expense | E27: =Financials!B11/Financials!$B$4 -> 0.16518619 | F27: =Financials!C11/Financials!$C$4 -> 0.044494054 | G27: =Financials!D11/Financials!$D$4 -> 0.071095827 | H27: =Financials!E11/Financials!$E$4 -> 0.091850791 | I27: =Financials!F11/Financials!$F$4 -> 0.09553986
B28: Other SG&A | E28: =Financials!B12/Financials!$B$4 -> 0.16518619 | F28: =Financials!C12/Financials!$C$4 -> 0.044494054 | G28: =Financials!D12/Financials!$D$4 -> 0.071095827 | H28: =Financials!E12/Financials!$E$4 -> 0.091850791 | I28: =Financials!F12/Financials!$F$4 -> 0.09553986
B29: Other Operating Expense | E29: =Financials!B13/Financials!$B$4 -> 0 | F29: =Financials!C13/Financials!$C$4 -> 0 | G29: =Financials!D13/Financials!$D$4 -> 0 | H29: =Financials!E13/Financials!$E$4 -> 0 | I29: =Financials!F13/Financials!$F$4 -> -0.003421568
B30: EBIT (Operating Income) | E30: =Financials!B14/Financials!$B$4 -> 0.092808414 | F30: =Financials!C14/Financials!$C$4 -> 0.13484013 | G30: =Financials!D14/Financials!$D$4 -> 0.12963592 | H30: =Financials!E14/Financials!$E$4 -> 0.1032674 | I30: =Financials!F14/Financials!$F$4 -> 0.095550861
B31: Nonoperating Income - Net | E31: =Financials!B15/Financials!$B$4 -> -0.058958689 | F31: =Financials!C15/Financials!$C$4 -> 0.047220279 | G31: =Financials!D15/Financials!$D$4 -> 0.027280725 | H31: =Financials!E15/Financials!$E$4 -> 0.0046614139 | I31: =Financials!F15/Financials!$F$4 -> 0.00018703105
... B66: Depreciation & Amortization Expense | E66: =Financials!B50/Financials!$B$4 -> 0.031954709 | F66: =Financials!C50/Financials!$C$4 -> 0.030379408 | G66: =Financials!D50/Financials!$D$4 -> 0.031869164 | H66: =Financials!E50/Financials!$E$4 -> 0.037092953 | I66: =Financials!F50/Financials!$F$4 -> 0.039705591
B73: b Standardized Annual Balance Sheet as a % of Total Assets
E75: 44196 | F75: 44561 | G75: 44926 | H75: 45291 | I75: 45657
B76: Cash & Short-Term Investments | E76: =Financials!B55/Financials!$B$88 -> 0.10120497 | F76: =Financials!C55/Financials!$C$88 -> 0.15262589 | G76: =Financials!D55/Financials!$D$88 -> 0.10678533 | H76: =Financials!E55/Financials!$E$88 -> 0.085693721 | I76: =Financials!F55/Financials!$F$88 -> 0.090166976
B77: Cash Only | E77: =Financials!B56/Financials!$B$88 -> 0.094699398 | F77: =Financials!C56/Financials!$C$88 -> 0.14775593 | G77: =Financials!D56/Financials!$D$88 -> 0.078763849 | H77: =Financials!E56/Financials!$E$88 -> 0.045246059 | I77: =Financials!F56/Financials!$F$88 -> 0.087227059
B78: Total Short Term Investments | E78: =Financials!B57/Financials!$B$88 -> 0.0065055762 | F78: =Financials!C57/Financials!$C$88 -> 0.0048699661 | G78: =Financials!D57/Financials!$D$88 -> 0.028021484 | H78: =Financials!E57/Financials!$E$88 -> 0.040447662 | I78: =Financials!F57/Financials!$F$88 -> 0.0029399172
B79: Short-Term Receivables | E79: =Financials!B58/Financials!$B$88 -> 0.17672414 | F79: =Financials!C58/Financials!$C$88 -> 0.18507312 | G79: =Financials!D58/Financials!$D$88 -> 0.18124684 | H79: =Financials!E58/Financials!$E$88 -> 0.16163541 | I79: =Financials!F58/Financials!$F$88 -> 0.15952619
B80: Accounts Receivables, Net | E80: =Financials!B59/Financials!$B$88 -> 0.17672414 | F80: =Financials!C59/Financials!$C$88 -> 0.18507312 | G80: =Financials!D59/Financials!$D$88 -> 0.18124684 | H80: =Financials!E59/Financials!$E$88 -> 0.16163541 | I80: =Financials!F59/Financials!$F$88 -> 0.15952619
B81: Accounts Receivables, Gross | E81: =Financials!B60/Financials!$B$88 -> 0.17893539 | F81: =Financials!C60/Financials!$C$88 -> 0.18691737 | G81: =Financials!D60/Financials!$D$88 -> 0.18329959 | H81: =Financials!E60/Financials!$E$88 -> 0.16341364 | I81: =Financials!F60/Financials!$F$88 -> 0.1614671
B82: Bad Debt/Doubtful Accounts | E82: =Financials!B61/Financials!$B$88 -> -0.002211255 | F82: =Financials!C61/Financials!$C$88 -> -0.0018442475 | G82: =Financials!D61/Financials!$D$88 -> -0.0020527529 | H82: =Financials!E61/Financials!$E$88 -> -0.0017782294 | I82: =Financials!F61/Financials!$F$88 -> -0.0019409162
B83: Other Receivables | E83: =Financials!B62/Financials!$B$88 -> 0 | F83: =Financials!C62/Financials!$C$88 -> 0 | G83: =Financials!D62/Financials!$D$88 -> 0 | H83: =Financials!E62/Financials!$E$88 -> 0 | I83: =Financials!F62/Financials!$F$88 -> 0
B84: Inventories | E84: =Financials!B63/Financials!$B$88 -> 0.0099346238 | F84: =Financials!C63/Financials!$C$88 -> 0.010330668 | G84: =Financials!D63/Financials!$D$88 -> 0.012499297 | H84: =Financials!E63/Financials!$E$88 -> 0.013195591 | I84: =Financials!F63/Financials!$F$88 -> 0.011788212
B85: Raw Materials | E85: =Financials!B64/Financials!$B$88 -> 0.0099346238 | F85: =Financials!C64/Financials!$C$88 -> 0.010330668 | G85: =Financials!D64/Financials!$D$88 -> 0 | H85: =Financials!E64/Financials!$E$88 -> 0 | I85: =Financials!F64/Financials!$F$88 -> 0
B86: Other Current Assets | E86: =Financials!B65/Financials!$B$88 -> 0.036069094 | F86: =Financials!C65/Financials!$C$88 -> 0.011223975 | G86: =Financials!D65/Financials!$D$88 -> 0.011838479 | H86: =Financials!E65/Financials!$E$88 -> 0.013449624 | I86: =Financials!F65/Financials!$F$88 -> 0.014100186
B87: Miscellaneous Current Assets | E87: =Financials!B66/Financials!$B$88 -> 0.036069094 | F87: =Financials!C66/Financials!$C$88 -> 0.011223975 | G87: =Financials!D66/Financials!$D$88 -> 0.011838479 | H87: =Financials!E66/Financials!$E$88 -> 0.013449624 | I87: =Financials!F66/Financials!$F$88 -> 0.014100186
... B136: Total Liabilities & Shareholders' Equity | E136: =Financials!B115/Financials!$B$88 -> 1 | F136: =Financials!C115/Financials!$C$88 -> 1 | G136: =Financials!D115/Financials!$D$88 -> 1 | H136: =Financials!E115/Financials!$E$88 -> 1 | I136: =Financials!F115/Financials!$F$88 -> 1
A138: 4 | B138: Standardized Annual Income Statement: Categorical Growth Rates
E141: 2020-2021 | F141: 2021-2022 | G141: 2022-2023 | H141: 2023-2024
...

Sheet Workshop #3
A3: Valuation Using Multiples of Comparable Firms
A5: Workshop 3
A6: Mathilde Sison, Averie Forshaw
A7: BUS 438
A8: Prof. Mahdi Rastad
A11: 2 | B11: Unadjusted Valuation Based on All Comparables
G12: EV/Sales | I12: EV/EBITDA | K12: P/E Ratio
B13: Median Value for all Comparable Firms | G13: =MEDIAN('Comparable Firms'!AZ5:AZ122) -> 1.17 | I13: =MEDIAN('Comparable Firms'!AX5:AX122) -> 9.12 | K13: =MEDIAN('Comparable Firms'!AO5:AO122) -> 16.815
A14: a | B14: UPS's Estimated Enterprise Value (in $000,000's) | G14: =G13*'Comparable Firms'!BY4 -> 104695.11 | I14: =I13*'Comparable Firms'!BZ4 -> 105974.4
A15: b | B15: UPS's Estimated Share Price | K15: =K13*Financials!F38 -> 113.71312
A30: 3 | B30: Unadjusted Valuation Based on Closest Comparables:
G31: EV/Sales | I31: EV/EBITDA | K31: P/E Ratio
B32: Median Value for Closest Comparable Firms | G32: =MEDIAN('Selective Comparable Firms'!AZ5:AZ9) -> 1.37 | I32: =MEDIAN('Selective Comparable Firms'!AX5:AX9) -> 11.36 | K32: =MEDIAN('Selective Comparable Firms'!AO5:AO9) -> 20.15
A33: a | B33: UPS's Estimated Enterprise Value (in $000,000's) | G33: =G32*'Selective Comparable Firms'!BY4 -> 122591.71 | I33: =I32*'Selective Comparable Firms'!BZ4 -> 132003.2
A34: b | B34: UPS's Estimated Share Price | K34: =K32*Financials!F38 -> 136.26639
A49: 8 | B49: Scatter Plots
A63: 9 | B63: Regression Results: Full Model
B65: SUMMARY OUTPUT
B67: Regression Statistics
B68: Multiple R | C68: 0.31708423
B69: R Square | C69: 0.10054241
B70: Adjusted R Square | C70: 0.036295439
B71: Standard Error | C71: 5.1827689
B72: Observations | C72: 46
B74: ANOVA
C75: df | D75: SS | E75: MS | F75: F | G75: Significance F
B76: Regression | C76: 3 | D76: 126.10769 | E76: 42.035897 | F76: 1.5649362 | G76: 0.21207129
B77: Residual | C77: 42 | D77: 1128.1659 | E77: 26.861093
B78: Total | C78: 45 | D78: 1254.2736
C80: Coefficients | D80: Standard Error | E80: t Stat | F80: P-value | G80: Lower 95% | H80: Upper 95% | I80: Lower 95.0% | J80: Upper 95.0%
B81: Intercept | C81: 6.1760073 | D81: 2.2737444 | E81: 2.7162276 | F81: 0.0095463067 | G81: 1.5874054 | H81: 10.764609 | I81: 1.5874054 | J81: 10.764609
B82: Historical growth in Revenues - Last 3 years | C82: 13.208067 | D82: 9.9502185 | E82: 1.3274148 | F82: 0.19154205 | G82: -6.8722865 | H82: 33.288421 | I82: -6.8722865 | J82: 33.288421
B83: Beta | C83: 3.2694495 | D83: 1.6733004 | E83: 1.9538927 | F83: 0.057394805 | G83: -0.10740752 | H83: 6.6463065 | I83: -0.10740752 | J83: 6.6463065
B84: Payout ratio | C84: 0.73061509 | D84: 2.8662392 | E84: 0.25490374 | F84: 0.80004151 | G84: -5.0536898 | H84: 6.51492 | I84: -5.0536898 | J84: 6.51492
A93: 10 | B93: Modified Regression Model: Reduced Model
B95: Dropped Payout Ratio
B96: SUMMARY OUTPUT
B98: Regression Statistics
B99: Multiple R | C99: 0.31488237
B100: R Square | C100: 0.099150907
...

Sheet Workshop #4
A3: Forcasting Growth
A5: Workshop 4
A6: Mathilde Sison, Averie Forshaw
A7: BUS 438
A8: Prof. Mahdi Rastad
B11: 3
B12: a | C12: First Guess Confidence Interval for 10-Year CAGR: | I12: [2%, 8%] | J12: Source: WS4 Exhibit 5.1
C13: median Estimate of 10-Year Industry CAGR: | I13: 0.05 | J13: Source: WS4 Exhibit 5.1
B16: b(i) | C16: Portfolio Momentum: E-commerce and global trade support moderate industry growth
B17: b(ii) | C17: Mergers & Acquisitions: UPS uses limited M&A, not a major growth driver
B18: b(iii) | C18: Market Share Performance: Highly competitive industry, large share gains are unlikely
B19: Conclusion: | C19: Growth is moderate, so 8% upper bound may be too high [2%, 6%]
B22: c | C22: Growth Sustainability: UPS does not depend on new product launches, as it provides recurring logistics services. Growth is sustainable but moderate and tied to economic cycles.
B25: d | C25: Growth Stability: Based on Exhibit 5.9, transportation growth over the last 40 years roughly ranges from: 2% to 10%. The spread is fairly wide spread, meaning growth is not very stable.
C27: Exhibit 5.9 Range of Median Industry Growth (40 Years) | I27: [2%, 10%]
B29: e | C29: Growth Convergence: Based on Exhibit 5.10 the firms with moderate growth (5-10%) tend to maintain about 5% growth short term. Over time, growth decays and converges toward industry medians. UPS's short term growth is estimated at approximately 5%, while long term growth is expected to converge towards 2-3%
C31: Exhibit 5.10 Short-Term Growth Estimate | I31: 0.05
C32: Exhibit 5.10 Long-Term Growth Estimate | I32: 2-3%
B34: f | C34: Analysts Estimates: Yahoo!Finance reports strong next-year growth (12.68%), but this is only short-term. UPS's 2026 revenue guidance implies only about 1% growth. Adjusting analyst optimism downward and considering long-term convergence, a reasonable growth estimate is 3-6% with a point estimate of 4%.
C36: Analysts Final Confidence Interval | I36: [3%, 6%]
C37: Analysts Final Point Estimate | I37: 0.04
B40: 4
B41: b(I,ii,iii)
B81: c
D87: Arithmetic | E87: Geometric | F87: Std. Dev. | G87: Range
B88: d(i,ii,iii) | C88: Revenue Growth | D88: =AVERAGE('UPS - Income Statement - Annual'!AH5:AH29) -> 0.046718153 | E88: =('UPS - Income Statement - Annual'!B6/'UPS - Income Statement - Annual'!AA6)^(1/25)-1 -> 0.044618152 | F88: =STDEV('UPS - Income Statement - Annual'!AH5:AH29) -> 0.066711607 | G88: =(MAX('UPS - Income Statement - Annual'!AH5:AH29)-MIN('UPS - Income Statement - Annual'!AH5:AH29)) -> 0.28419519
C89: EBIT Growth | D89: =AVERAGE('UPS - Income Statement - Annual'!AK5:AK29) -> 0.4874218 | E89: =('UPS - Income Statement - Annual'!B16/'UPS - Income Statement - Annual'!AA16)^(1/25)-1 -> 0.022486546 | F89: =STDEV('UPS - Income Statement - Annual'!AK5:AK29) -> 1.8729447 | G89: =(MAX('UPS - Income Statement - Annual'!AK5:AK29)-MIN('UPS - Income Statement - Annual'!AK5:AK29)) -> 9.2243049
C90: EPS Growth | D90: =AVERAGE('UPS - Income Statement - Annual'!AN5:AN29) -> 0.74519584 | E90: =('UPS - Income Statement - Annual'!B24/'UPS - Income Statement - Annual'!AA24)^(1/25)-1 -> 0.038682477 | F90: =STDEV('UPS - Income Statement - Annual'!AN5:AN29) -> 2.3746326 | G90: =(MAX('UPS - Income Statement - Annual'!AN5:AN29)-MIN('UPS - Income Statement - Annual'!AN5:AN29)) -> 9.4846578
C92: Geometric Average is More reliable because it reflects compounded growth.
B95: e(i) | C95: SUMMARY OUTPUT
C96: Ln(Revenue) vs. Time
C98: Regression Statistics
C99: Multiple R | D99: 0.9753217
C100: R Square | D100: 0.95125242
C101: Adjusted R Square | D101: 0.94922127
C102: Standard Error | D102: 0.083233744
C103: Observations | D103: 26
C105: ANOVA
D106: df | E106: SS | F106: MS | G106: F | H106: Significance F
C107: Regression | D107: 1 | E107: 3.2445376 | F107: 3.2445376 | G107: 468.33212 | H107: 2.9699467e-17
...

Sheet Workshop #5
B2: Capital Budgeting and Pro-Forma Analysis
B4: Workshop 5
B5: Mathilde Sison, Averie Forshaw
B6: BUS 438
B7: Prof. Mahdi Rastad
B9: 1 | D9: 2020 | E9: 2021 | F9: 2022 | G9: 2023 | H9: 2024
C10: Taxable Income | D10: =Financials!B34+Financials!B28 -> 1844 | E10: =Financials!C34+Financials!C28 -> 16595 | F10: =Financials!D34+Financials!D28 -> 14825 | G10: =Financials!E34+Financials!E28 -> 8573 | H10: =Financials!F34+Financials!F28 -> 7442
C11: Taxation | D11: =Financials!B28 -> 501 | E11: =Financials!C28 -> 3705 | F11: =Financials!D28 -> 3277 | G11: =Financials!E28 -> 1865 | H11: =Financials!F28 -> 1660
C12: Tax Rate | D12: =D11/D10 -> 0.27169197 | E12: =E11/E10 -> 0.22326002 | F12: =F11/F10 -> 0.22104553 | G12: =G11/G10 -> 0.21754345 | H12: =H11/H10 -> 0.22305832
B14: a(i) | C14: Medium-Term Growth Rate (g1) | G14: ='Workshop #4'!G139 -> 0.04
C15: Long-Term Growth Rate (g2) | G15: ='Workshop #4'!G140 -> 0.025
C16: Growth Rate Being Used | G16: =G14 -> 0.04
C17: Average Tax-Rate (2020-2024) | G17: =AVERAGE(D12:H12) -> 0.23131986
C18: Target Payout Ratio | G18: =AVERAGE('Workshop #2'!C280:G280) -> 1.0307268
C19: Cost of Debt | G19: ='Workshop #6'!E199 -> 0.048738912
C20: Risk-Free Rate | G20: ='Workshop #6'!D28 -> 0.0426
C22: Original Forecast | M22: 1st Revision
C23: Income Statement | D23: % of Sales | H23: Forecasted Years | M23: Income Statement | N23: % of Sales | R23: Forecasted Years
C24: Report Date | E24: =2024 -> 2024 | F24: 2025 | G24: 2026 | H24: 2027 | I24: 2028 | J24: 2029 | M24: Report Date | O24: =E24 -> 2024 | P24: =F24 -> 2025 | Q24: =G24 -> 2026 | R24: =H24 -> 2027 | S24: =I24 -> 2028 | T24: =J24 -> 2029
C25: Sales | D25: =E25/$E$25 -> 1 | E25: =Financials!$F$4 -> 90894 | F25: =E25*(1+$G$16) -> 94529.76 | G25: =F25*(1+$G$16) -> 98310.95 | H25: =G25*(1+$G$16) -> 102243.39 | I25: =H25*(1+$G$16) -> 106333.12 | J25: =I25*(1+$G$16) -> 110586.45 | M25: Sales | N25: =O25/$E$25 -> 1 | O25: =Financials!$F$4 -> 90894 | P25: =O25*(1+$G$16) -> 94529.76 | Q25: =P25*(1+$G$16) -> 98310.95 | R25: =Q25*(1+$G$16) -> 102243.39 | S25: =R25*(1+$G$16) -> 106333.12 | T25: =S25*(1+$G$16) -> 110586.45
C26: COGS | D26: =E26/$E$25 -> 0.81233085 | E26: =Financials!$F$5 -> 73836 | F26: =F$25*$D26 -> 76789.44 | G26: =G$25*$D26 -> 79861.018 | H26: =H$25*$D26 -> 83055.458 | I26: =I$25*$D26 -> 86377.677 | J26: =J$25*$D26 -> 89832.784 | M26: COGS | N26: =O26/$E$25 -> 0.81233085 | O26: =Financials!$F$5 -> 73836 | P26: =P$25*$D26 -> 76789.44 | Q26: =Q$25*$D26 -> 79861.018 | R26: =R$25*$D26 -> 83055.458 | S26: =S$25*$D26 -> 86377.677 | T26: =T$25*$D26 -> 89832.784
C27: Gross Income | D27: =E27/$E$25 -> 0.18766915 | E27: =E25-E26 -> 17058 | F27: =F25-F26 -> 17740.32 | G27: =G25-G26 -> 18449.933 | H27: =H25-H26 -> 19187.93 | I27: =I25-I26 -> 19955.447 | J27: =J25-J26 -> 20753.665 | M27: Gross Income | N27: =O27/$E$25 -> 0.18766915 | O27: =O25-O26 -> 17058 | P27: =P25-P26 -> 17740.32 | Q27: =Q25-Q26 -> 18449.933 | R27: =R25-R26 -> 19187.93 | S27: =S25-S26 -> 19955.447 | T27: =T25-T26 -> 20753.665
C28: Depreciation & Amortizaton | D28: =E28/$E$25 -> 0.039705591 | E28: =Financials!$F$8+Financials!$F$9 -> 3609 | F28: =F$25*$D28 -> 3753.36 | G28: =G$25*$D28 -> 3903.4944 | H28: =H$25*$D28 -> 4059.6342 | I28: =I$25*$D28 -> 4222.0195 | J28: =J$25*$D28 -> 4390.9003 | M28: Depreciation & Amortizaton | N28: =O28/$E$25 -> 0.039705591 | O28: =Financials!$F$8+Financials!$F$9 -> 3609 | P28: =P$25*$D28 -> 3753.36 | Q28: =Q$25*$D28 -> 3903.4944 | R28: =R$25*$D28 -> 4059.6342 | S28: =S$25*$D28 -> 4222.0195 | T28: =T$25*$D28 -> 4390.9003
C29: SG&A | D29: =E29/$E$25 -> 0.09553986 | E29: =Financials!$F$11 -> 8684 | F29: =F$25*$D29 -> 9031.36 | G29: =G$25*$D29 -> 9392.6144 | H29: =H$25*$D29 -> 9768.319 | I29: =I$25*$D29 -> 10159.052 | J29: =J$25*$D29 -> 10565.414 | M29: SG&A | N29: =O29/$E$25 -> 0.09553986 | O29: =Financials!$F$11 -> 8684 | P29: =P$25*$D29 -> 9031.36 | Q29: =Q$25*$D29 -> 9392.6144 | R29: =R$25*$D29 -> 9768.319 | S29: =S$25*$D29 -> 10159.052 | T29: =T$25*$D29 -> 10565.414
C30: Other Operating Expense | D30: =E30/$E$25 -> 0.003421568 | E30: =-Financials!$F$13 -> 311 | F30: =F$25*$D30 -> 323.44 | G30: =G$25*$D30 -> 336.3776 | H30: =H$25*$D30 -> 349.8327 | I30: =I$25*$D30 -> 363.82601 | J30: =J$25*$D30 -> 378.37905 | M30: Other Operating Expense | N30: =O30/$E$25 -> 0.003421568 | O30: =-Financials!$F$13 -> 311 | P30: =P$25*$D30 -> 323.44 | Q30: =Q$25*$D30 -> 336.3776 | R30: =R$25*$D30 -> 349.8327 | S30: =S$25*$D30 -> 363.82601 | T30: =T$25*$D30 -> 378.37905
C31: Operating Income (EBIT) | D31: =E31/$E$25 -> 0.095550861 | E31: =E27-E29+E30 -> 8685 | F31: =F27-F29+F30 -> 9032.4 | G31: =G27-G29+G30 -> 9393.696 | H31: =H27-H29+H30 -> 9769.4438 | I31: =I27-I29+I30 -> 10160.222 | J31: =J27-J29+J30 -> 10566.63 | M31: Operating Income (EBIT) | N31: =O31/$E$25 -> 0.095550861 | O31: =O27-O29+O30 -> 8685 | P31: =P27-P29+P30 -> 9032.4 | Q31: =Q27-Q29+Q30 -> 9393.696 | R31: =R27-R29+R30 -> 9769.4438 | S31: =S27-S29+S30 -> 10160.222 | T31: =T27-T29+T30 -> 10566.63
C32: Other Income (Expense) | D32: =E32/$E$25 -> 0.00018703105 | E32: =Financials!$F$17 -> 17 | F32: =F$25*$D32 -> 17.68 | G32: =G$25*$D32 -> 18.3872 | H32: =H$25*$D32 -> 19.122688 | I32: =I$25*$D32 -> 19.887596 | J32: =J$25*$D32 -> 20.683099 | M32: Other Income (Expense) | N32: =O32/$E$25 -> 0.00018703105 | O32: =Financials!$F$17 -> 17 | P32: =P$25*$D32 -> 17.68 | Q32: =Q$25*$D32 -> 18.3872 | R32: =R$25*$D32 -> 19.122688 | S32: =S$25*$D32 -> 19.887596 | T32: =T$25*$D32 -> 20.683099
C33: Interest Expense | D33: =E33/$E$25 -> 0.0094725724 | E33: =Financials!$F$18 -> 861 | F33: =$E$33 -> 861 | G33: =$E$33 -> 861 | H33: =$E$33 -> 861 | I33: =$E$33 -> 861 | J33: =$E$33 -> 861 | M33: Interest Expense | N33: =O33/$E$25 -> 0.0094725724 | O33: =Financials!$F$18 -> 861 | P33: =(O60+O63)*$G$19-(O45-E45)*$G$20 -> 1250.2506 | Q33: =(P60+P63)*$G$19-(P45-F45)*$G$20 -> 590.47192 | R33: =(Q60+Q63)*$G$19-(Q45-G45)*$G$20 -> 671.51927 | S33: =(R60+R63)*$G$19-(R45-H45)*$G$20 -> 763.09752 | T33: =(S60+S63)*$G$19-(S45-I45)*$G$20 -> 858.3389
C34: Unusual Expense | D34: =E34/$E$25 -> 0.0043897287 | E34: =Financials!$F$21 -> 399 | F34: =F$25*$D34 -> 414.96 | G34: =G$25*$D34 -> 431.5584 | H34: =H$25*$D34 -> 448.82074 | I34: =I$25*$D34 -> 466.77357 | J34: =J$25*$D34 -> 485.44451 | M34: Unusual Expense | N34: =O34/$E$25 -> 0.0043897287 | O34: =Financials!$F$21 -> 399 | P34: =P$25*$D34 -> 414.96 | Q34: =Q$25*$D34 -> 431.5584 | R34: =R$25*$D34 -> 448.82074 | S34: =S$25*$D34 -> 466.77357 | T34: =T$25*$D34 -> 485.44451
C35: Earnings Before Tax | D35: =E35/$E$25 -> 0.081875591 | E35: =E31+E32-E33-E34 -> 7442 | F35: =F31+F32-F33-F34 -> 7774.12 | G35: =G31+G32-G33-G34 -> 8119.5248 | H35: =H31+H32-H33-H34 -> 8478.7458 | I35: =I31+I32-I33-I34 -> 8852.3356 | J35: =J31+J32-J33-J34 -> 9240.869 | M35: Earnings Before Tax | N35: =O35/$E$25 -> 0.081875591 | O35: =O31+O32-O33-O34 -> 7442 | P35: =P31+P32-P33-P34 -> 7384.8694 | Q35: =Q31+Q32-Q33-Q34 -> 8390.0529 | R35: =R31+R32-R33-R34 -> 8668.2265 | S35: =S31+S32-S33-S34 -> 8950.2381 | T35: =T31+T32-T33-T34 -> 9243.5302
C36: Income Tax | D36: =E36/$E$25 -> 0.018263032 | E36: =Financials!$F$28 -> 1660 | F36: =F$25*$D36 -> 1726.4 | G36: =G$25*$D36 -> 1795.456 | H36: =H$25*$D36 -> 1867.2742 | I36: =I$25*$D36 -> 1941.9652 | J36: =J$25*$D36 -> 2019.6438 | M36: Income Tax | N36: =O36/$E$25 -> 0.018263032 | O36: =Financials!$F$28 -> 1660 | P36: =P$25*$D36 -> 1726.4 | Q36: =Q$25*$D36 -> 1795.456 | R36: =R$25*$D36 -> 1867.2742 | S36: =S$25*$D36 -> 1941.9652 | T36: =T$25*$D36 -> 2019.6438
C37: Net Income | D37: =E37/$E$25 -> 0.06361256 | E37: =E35-E36 -> 5782 | F37: =F35-F36 -> 6047.72 | G37: =G35-G36 -> 6324.0688 | H37: =H35-H36 -> 6611.4716 | I37: =I35-I36 -> 6910.3704 | J37: =J35-J36 -> 7221.2252 | M37: Net Income | N37: =O37/$E$25 -> 0.06361256 | O37: =O35-O36 -> 5782 | P37: =P35-P36 -> 5658.4694 | Q37: =Q35-Q36 -> 6594.5969 | R37: =R35-R36 -> 6800.9523 | S37: =S35-S36 -> 7008.2729 | T37: =T35-T36 -> 7223.8863
C39: Dividends | D39: =E39/$E$25 -> 0.05939886 | E39: =-Financials!$F$150 -> 5399 | F39: =F$25*$D39 -> 5614.96 | G39: =G$25*$D39 -> 5839.5584 | H39: =H$25*$D39 -> 6073.1407 | I39: =I$25*$D39 -> 6316.0664 | J39: =J$25*$D39 -> 6568.709 | M39: Dividends | N39: =O39/$E$25 -> 0.05939886 | O39: =-Financials!$F$150 -> 5399 | P39: =P$25*$D39 -> 5614.96 | Q39: =Q$25*$D39 -> 5839.5584 | R39: =R$25*$D39 -> 6073.1407 | S39: =S$25*$D39 -> 6316.0664 | T39: =T$25*$D39 -> 6568.709
C40: Incremental Retained Earnings | D40: =E40/$E$25 -> 0.22974014 | E40: =Financials!$F$107 -> 20882 | F40: =F$25*$D40 -> 21717.28 | G40: =G$25*$D40 -> 22585.971 | H40: =H$25*$D40 -> 23489.41 | I40: =I$25*$D40 -> 24428.986 | J40: =J$25*$D40 -> 25406.146 | M40: Incremental Retained Earnings | N40: =O40/$E$25 -> 0.22974014 | O40: =Financials!$F$107 -> 20882 | P40: =P$25*$D40 -> 21717.28 | Q40: =Q$25*$D40 -> 22585.971 | R40: =R$25*$D40 -> 23489.41 | S40: =S$25*$D40 -> 24428.986 | T40: =T$25*$D40 -> 25406.146
M41: Diff in Incr. Ret. Earnings | O41: =O40-E40 -> 0 | P41: =P40-F40 -> 0 | Q41: =Q40-G40 -> 0 | R41: =R40-H40 -> 0 | S41: =S40-I40 -> 0 | T41: =T40-J40 -> 0
C43: Balance Sheet | M43: Balance Sheet
C44: Report Date | E44: 2024 | F44: 2025 | G44: 2026 | H44: 2027 | I44: 2028 | J44: 2029 | M44: Report Date | O44: =E44 -> 2024 | P44: =F44 -> 2025 | Q44: =G44 -> 2026 | R44: =H44 -> 2027 | S44: =I44 -> 2028 | T44: =J44 -> 2029
C45: Cash & ST Investments | D45: =E45/$E$25 -> 0.069509539 | E45: =Financials!$F$55 -> 6318 | F45: =F$25*$D45 -> 6570.72 | G45: =G$25*$D45 -> 6833.5488 | H45: =H$25*$D45 -> 7106.8908 | I45: =I$25*$D45 -> 7391.1664 | J45: =J$25*$D45 -> 7686.813 | M45: Cash & ST Investments | N45: =O45/$E$25 -> 0.069509539 | O45: =Financials!$F$55 -> 6318 | P45: =P$25*$D45 -> 6570.72 | Q45: =Q$25*$D45 -> 6833.5488 | R45: =R$25*$D45 -> 7106.8908 | S45: =S$25*$D45 -> 7391.1664 | T45: =T$25*$D45 -> 7686.813
C46: Receivables ST | D46: =E46/$E$25 -> 0.12447466 | E46: =Financials!$F$60 -> 11314 | F46: =F$25*$D46 -> 11766.56 | G46: =G$25*$D46 -> 12237.222 | H46: =H$25*$D46 -> 12726.711 | I46: =I$25*$D46 -> 13235.78 | J46: =J$25*$D46 -> 13765.211 | M46: Receivables ST | N46: =O46/$E$25 -> 0.12447466 | O46: =Financials!$F$60 -> 11314 | P46: =P$25*$D46 -> 11766.56 | Q46: =Q$25*$D46 -> 12237.222 | R46: =R$25*$D46 -> 12726.711 | S46: =S$25*$D46 -> 13235.78 | T46: =T$25*$D46 -> 13765.211
C47: Bad Debt | D47: =E47/$E$25 -> 0.0014962484 | E47: =-Financials!$F$61 -> 136 | F47: =F$25*$D47 -> 141.44 | G47: =G$25*$D47 -> 147.0976 | H47: =H$25*$D47 -> 152.9815 | I47: =I$25*$D47 -> 159.10076 | J47: =J$25*$D47 -> 165.46479 | M47: Bad Debt | N47: =O47/$E$25 -> 0.0014962484 | O47: =-Financials!$F$61 -> 136 | P47: =P$25*$D47 -> 141.44 | Q47: =Q$25*$D47 -> 147.0976 | R47: =R$25*$D47 -> 152.9815 | S47: =S$25*$D47 -> 159.10076 | T47: =T$25*$D47 -> 165.46479
...

Sheet Workshop #6
B3: Estimating Cost of Capital
B5: Workshop 6
B6: Mathilde Sison, Averie Forshaw
B7: BUS 438
B8: Prof. Mahdi Rastad
A12: 1 | C12: Date Accessed: 1/31/26
B13: a(i) | C13: Year(s) to Maturity | D13: T-Bond Yield | E13: TIPS Yield
C14: =1/12 -> 0.083333333 | D14: 0.0372
C15: =3/12 -> 0.25 | D15: 0.0367
C16: =6/12 -> 0.5 | D16: 0.0361
C17: =1 -> 1 | D17: 0.0348
C18: 3 | D18: 0.036
C19: 5 | D19: 0.0379 | E19: =1.26% -> 0.0126
C20: 7 | D20: 0.0401 | E20: =1.59% -> 0.0159
C21: 10 | D21: 0.0426 | E21: =1.9% -> 0.019
C22: 20 | D22: 0.0482 | E22: =2.38% -> 0.0238
C23: 30 | D23: 0.0487 | E23: =2.6% -> 0.026
D27: T-Bond Yield | E27: TIPS Yield
B28: a(ii) | C28: Risk Free Rate Chosen | D28: ='Workshop #8'!D128 -> 0.0426 | E28: =E21 -> 0.019
B30: b(ii) | C30: Real Rate = Nominal Rate - Inflation
C31: Nominal Rate = Real Rate + Inflation
C32: TIPS Rate = Risk-Free Rate - Inflation
C33: Risk-Free Rate = TIPS Rate + Inflation
C34: MRP = Nom. Exp. Mkt. Return - Risk-Free Rate
C35: MRP = (Real Rate + Inflation) - (TIPS Rate + Inflation)
C36: MRP = Real Rate - TIPS Rate
C37: From Exhibit 11.6: Real Rate = | F37: 0.07
C38: TIPS Rate Being Used = | F38: =E28 -> 0.019
C39: Estimated MRP = | F39: =F37-F38 -> 0.051
B41: c(i)
C57: UPS vs. S&P 500 (60-Month)
C59: Regression Statistics
C60: Multiple R | D60: 0.60503922
C61: R Square | D61: 0.36607246
C62: Adjusted R Square | D62: 0.35514268
C63: Standard Error | D63: 0.064425478
C64: Observations | D64: 60
C66: ANOVA
D67: df | E67: SS | F67: MS | G67: F | H67: Significance F
C68: Regression | D68: 1 | E68: 0.1390179 | F68: 0.1390179 | G68: 33.493107 | H68: 3.0475922e-07
...

Sheet Workshop #7
B2: Valuation and the Second Driver: ROIC
B4: Workshop 7
B5: Mathilde Sison, Averie Forshaw
B6: BUS 438
B7: Prof. Mahdi Rastad
B10: 1
B11: a | C11: UPS | F11: 2020 | G11: 2021 | H11: 2022 | I11: 2023 | J11: 2024
C12: EBIT | F12: =Financials!B14 -> 7836 | G12: =Financials!C14 -> 13107 | H12: =Financials!D14 -> 12968 | I12: =Financials!E14 -> 9371 | J12: =Financials!F14 -> 8685
C13: 1- Tax Rate | F13: =1-(Financials!B28/Financials!B27) -> 0.72830803 | G13: =1-(Financials!C28/Financials!C27) -> 0.77673998 | H13: =1-(Financials!D28/Financials!D27) -> 0.77895447 | I13: =1-(Financials!E28/Financials!E27) -> 0.78245655 | J13: =1-(Financials!F28/Financials!F27) -> 0.77694168
C14: NOPLAT | F14: =F12*F13 -> 5707.0217 | G14: =G12*G13 -> 10180.731 | H14: =H12*H13 -> 10101.482 | I14: =I12*I13 -> 7332.4003 | J14: =J12*J13 -> 6747.7385
C15: PP&E | F15: =Financials!B68 -> 35327 | G15: =Financials!C68 -> 37037 | H15: =Financials!D68 -> 38474 | I15: =Financials!E68 -> 41253 | J15: =Financials!F68 -> 41328
C16: Working Capital | F16: =Financials!B67-Financials!B94 -> 3200 | G16: =Financials!C67-Financials!C94 -> 7365 | H16: =Financials!D67-Financials!D94 -> 4077 | I16: =Financials!E67-Financials!E94 -> 1737 | J16: =Financials!F67-Financials!F94 -> 2869
C17: Less Cash | F17: =Financials!B55 -> 6316 | G17: =Financials!C55 -> 10593 | H17: =Financials!D55 -> 7595 | I17: =Financials!E55 -> 6072 | J17: =Financials!F55 -> 6318
C18: Invested Capital | F18: =F15+F16-F17 -> 32211 | G18: =G15+G16-G17 -> 33809 | H18: =H15+H16-H17 -> 34956 | I18: =I15+I16-I17 -> 36918 | J18: =J15+J16-J17 -> 37879
C19: ROIC | F19: =F14/F18 -> 0.17717617 | G19: =G14/G18 -> 0.30112488 | H19: =H14/H18 -> 0.28897704 | I19: =I14/I18 -> 0.19861315 | J19: =J14/J18 -> 0.1781393
C21: Average Historic ROIC | F21: =AVERAGE(F19:J19) -> 0.22880611
C22: Noirmalized UPS ROIC | F22: =AVERAGE(F19,I19,J19) -> 0.18464287
B24: b | C24: Company | D24: ROIC
C25: Deutsche Post AG (XTRA:DHL) | D25: ='Selective Comparable Firms'!BK5 -> 0.0955
C26: TFI International Inc. (TSX:TFII) | D26: ='Selective Comparable Firms'!BK6 -> 0.1145
C27: FedEx Corporation (NYSE:FDX) | D27: ='Selective Comparable Firms'!BK8 -> 0.099165988
C28: Industry Average ROIC | D28: =AVERAGE(D25:D27) -> 0.10305533
B30: c | C30: Forecasted long-term ROIC from Exhibits 4.6 and 4.8 | H30: 0.13
C31: Forecasted long-term ROIC from average of UPS and in dustry historic ROIC | H31: =AVERAGE(F22,D28) -> 0.1438491
C32: UPS's Estimated Long-Term ROIC | E32: =AVERAGE(H30,H31) -> 0.13692455
B35: 2
C36: DCF Method
C37: WACC (WS6) | E37: ='Workshop #6'!E239 -> 0.086843826
C38: Long-Term Growth Rate (g2)(WS4) | E38: ='Workshop #4'!G140 -> 0.025
D40: 2024 | E40: 2025 | F40: 2026 | G40: 2027 | H40: 2028 | I40: 2029
C41: FCF (in $000,000's) | D41: =Financials!$F$133+Financials!$F$135 -> 307 | E41: =D$41*(100%+'Workshop #4'!$G$139) -> 319.28 | F41: =E$41*(100%+'Workshop #4'!$G$139) -> 332.0512 | G41: =F$41*(100%+'Workshop #4'!$G$139) -> 345.33325 | H41: =G$41*(100%+'Workshop #4'!$G$139) -> 359.14658 | I41: =H$41*(100%+'Workshop #4'!$G$139) -> 373.51244
C42: Terminal Value | I42: =(I41*(100%+E38))/(E37-E38) -> 6190.5978
C43: PV (FCFs) | E43: =E41/((100%+$E$37)^1) -> 293.76806 | F43: =F41/((100%+$E$37)^2) -> 281.10642 | G43: =G41/((100%+$E$37)^3) -> 268.99051 | H43: =H41/((100%+$E$37)^4) -> 257.39681 | I43: =I41/((100%+$E$37)^5) -> 246.30281
C44: PV (terminal Value) | D44: =I42/((100%+E37)^5) -> 4082.2244
B46: b(i) | C46: Total PV of FCFs | D46: =SUM(E43:I43) -> 1347.5646
C47: PV (Terminal Value) | D47: =D44 -> 4082.2244
C48: Enterprise Value | D48: =D46+D44 -> 5429.789
B49: b(ii) | C49: EV w/ Mid-Year Correction | D49: =((100%+E37)^0.5)*D48 -> 5660.6529
B50: b(iii) | C50: Plus: Cash | D50: ='Workshop #5'!E45 -> 6318
B51: b(iv) | C51: Less: Total Debt | D51: ='Workshop #5'!E60+'Workshop #5'!E63 -> 25652
...

Sheet Workshop #8
B3: Sensitivity Analysis and Comparison of Valuation Models
B5: Workshop 8
B6: Mathilde Sison, Averie Forshaw
B7: BUS 438
B8: Prof. Mahdi Rastad
B10: 1a | C10: i
B52: 1b | C52: I, ii | D52: 2020 | E52: 2021 | F52: 2022 | G52: 2023 | H52: 2024 | I52: 2025 | J52: 2026 | K52: 2027 | L52: 2028 | M52: 2029
C53: Profitability Ratios:
C54: Operating Margin | D54: ='Workshop #2'!C272 -> 0.092808414 | E54: ='Workshop #2'!D272 -> 0.13484013 | F54: ='Workshop #2'!E272 -> 0.12963592 | G54: ='Workshop #2'!F272 -> 0.1032674 | H54: ='Workshop #2'!G272 -> 0.095550861 | I54: ='Workshop #5'!P31/'Workshop #5'!P25 -> 0.095550861 | J54: ='Workshop #5'!Q31/'Workshop #5'!Q25 -> 0.095550861 | K54: ='Workshop #5'!R31/'Workshop #5'!R25 -> 0.095550861 | L54: ='Workshop #5'!S31/'Workshop #5'!S25 -> 0.095550861 | M54: ='Workshop #5'!T31/'Workshop #5'!T25 -> 0.095550861
C55: Net Profit Margin | D55: ='Workshop #2'!C273 -> 0.015906291 | E55: ='Workshop #2'!D273 -> 0.13260771 | F55: ='Workshop #2'!E273 -> 0.11544075 | G55: ='Workshop #2'!F273 -> 0.073921428 | H55: ='Workshop #2'!G273 -> 0.06361256 | I55: ='Workshop #5'!P37/'Workshop #5'!P26 -> 0.073688119 | J55: ='Workshop #5'!Q37/'Workshop #5'!Q26 -> 0.082575918 | K55: ='Workshop #5'!R37/'Workshop #5'!R26 -> 0.081884471 | L55: ='Workshop #5'!S37/'Workshop #5'!S26 -> 0.081135233 | M55: ='Workshop #5'!T37/'Workshop #5'!T26 -> 0.080414811
C56: Return on Equity (ROE | D56: ='Workshop #2'!C274 -> 2.0074738 | E56: ='Workshop #2'!D274 -> 0.90335693 | F56: ='Workshop #2'!E274 -> 0.58314397 | G56: ='Workshop #2'!F274 -> 0.38743214 | H56: ='Workshop #2'!G274 -> 0.34533835 | I56: ='Workshop #5'!P37/'Workshop #5'!O68 -> 0.33796031 | J56: ='Workshop #5'!Q37/'Workshop #5'!P68 -> 0.37872296 | K56: ='Workshop #5'!R37/'Workshop #5'!Q68 -> 0.37555173 | L56: ='Workshop #5'!S37/'Workshop #5'!R68 -> 0.37211546 | M56: ='Workshop #5'!T37/'Workshop #5'!S68 -> 0.36881134
C57: Financial Strength Ratios:
C58: Current Ratio | D58: ='Workshop #2'!C276 -> 1.0108359 | E58: ='Workshop #2'!D276 -> 1.2587964 | F58: ='Workshop #2'!E276 -> 1.3858654 | G58: ='Workshop #2'!F276 -> 1.3233663 | H58: ='Workshop #2'!G276 -> 1.3139685 | I58: ='Workshop #5'!P50/'Workshop #5'!P62 -> 1.2030374 | J58: ='Workshop #5'!Q50/'Workshop #5'!Q62 -> 1.2318134 | K58: ='Workshop #5'!R50/'Workshop #5'!R62 -> 1.2608114 | L58: ='Workshop #5'!S50/'Workshop #5'!S62 -> 1.2900114 | M58: ='Workshop #5'!T50/'Workshop #5'!T62 -> 1.3193929
C59: Book Debt-to-Equity Ratio | D59: ='Workshop #2'!C277 -> 0.28205804 | E59: ='Workshop #2'!D277 -> 0.012280238 | F59: ='Workshop #2'!E277 -> 0.0079728348 | G59: ='Workshop #2'!F277 -> 0.010056207 | H59: ='Workshop #2'!G277 -> 0.010586761 | I59: ='Workshop #5'!P63/('Workshop #5'!P68) -> 0.54810506 | J59: ='Workshop #5'!Q63/('Workshop #5'!Q68) -> 0.61884954 | K59: ='Workshop #5'!R63/('Workshop #5'!R68) -> 0.69481379 | L59: ='Workshop #5'!S63/('Workshop #5'!S68) -> 0.76785633 | M59: ='Workshop #5'!T63/('Workshop #5'!T68) -> 0.83808954
C60: Interest Coverage Ratio | D60: ='Workshop #2'!C279 -> 11.45614 | E60: ='Workshop #2'!D279 -> 19.190337 | F60: ='Workshop #2'!E279 -> 18.685879 | G60: ='Workshop #2'!F279 -> 12.091613 | H60: ='Workshop #2'!G279 -> 10.087108 | I60: ='Workshop #5'!P37/'Workshop #5'!P33 -> 4.5258683 | J60: ='Workshop #5'!Q37/'Workshop #5'!Q33 -> 11.16835 | K60: ='Workshop #5'!R37/'Workshop #5'!R33 -> 10.12771 | L60: ='Workshop #5'!S37/'Workshop #5'!S33 -> 9.1839807 | M60: ='Workshop #5'!T37/'Workshop #5'!T33 -> 8.4161237
C61: Payout Ratio | D61: ='Workshop #2'!C280 -> 2.620144 | E61: ='Workshop #2'!D280 -> 0.27790833 | F61: ='Workshop #2'!E280 -> 0.46068633 | G61: ='Workshop #2'!F280 -> 0.83076923 | H61: ='Workshop #2'!G280 -> 0.96412622 | I61: ='Workshop #5'!P39/'Workshop #5'!P37 -> 0.99231074 | J61: ='Workshop #5'!Q39/'Workshop #5'!Q37 -> 0.8855065 | K61: ='Workshop #5'!R39/'Workshop #5'!R37 -> 0.89298388 | L61: ='Workshop #5'!S39/'Workshop #5'!S37 -> 0.90123008 | M61: ='Workshop #5'!T39/'Workshop #5'!T37 -> 0.90930404
C92: iii
B94: 1c | D94: DCF | E94: APV | F94: Current Market Value
C95: Share Price | D95: ='Workshop #7'!D54 -> -15.992219 | E95: ='Workshop #7'!D107 -> 111.7856 | F95: ='Workshop #2'!D11 -> 108.03
C96: Market Cap | D96: ='Workshop #7'!D52 -> -13673.347 | E96: ='Workshop #7'!D105 -> 95576.691 | F96: =(F95)*Financials!F39 -> 92365.65
C97: Error Margin | D97: =(D96-F96)/F96 -> -1.148035 | E97: =(E96-F96)/F96 -> 0.034764454 | F97: 0
C99: Firm Value (Average of APV and DCF Value) | E99: =AVERAGE(D96:E96) -> 40951.672
C100: Corresponding Average Share Price | E100: =AVERAGE(D95:E95) -> 47.896693
C101: % Difference | E101: =(E99-F96)/F96 -> -0.55663526
B104: 2a | C104: Sensitivity Analysis:
B105: I,ii | C105: Driver | D105: % Change | E105: Value Original | F105: Value After | G105: Impact on Original Value
C106: Risk-Free Rate | D106: 1% increase | E106: =$E$99 -> 40951.672 | F106: 94130 | G106: =ABS(E106-F106) -> 53178.328
C107: Beta | D107: 1% increase | E107: =$E$99 -> 40951.672 | F107: 95013 | G107: =ABS(E107-F107) -> 54061.328
C108: Cost of Debt | D108: 1% increase | E108: =$E$99 -> 40951.672 | F108: 95276 | G108: =ABS(E108-F108) -> 54324.328
C109: Growth Rate (g2) | D109: 1% increase | E109: =$E$99 -> 40951.672 | F109: 95767 | G109: =ABS(E109-F109) -> 54815.328
B125: iii | C125: Growth rate has the biggest impact on UPS.
B127: 2b
B128: i | C128: Risk-free Rate | D128: ='Workshop #6'!D21 -> 0.0426
C129: Beta | D129: =AVERAGE('Workshop #6'!D81,'Workshop #6'!E189) -> 1.0426268
C130: Cost of Debt | D130: ='Workshop #6'!E198 -> 0.048738912
C131: Growth Rate (g2) | D131: 0.025
D134: Beta
C135: Firm Value | D135: =E99 -> 40951.672 | E135: =F135*0.99 -> 1.0015431 | F135: =G135*0.99 -> 1.0116597 | G135: =H135*0.99 -> 1.0218785 | H135: =I135*0.99 -> 1.0322005 | I135: =AVERAGE('Workshop #6'!E222:F222) -> 1.0426268 | J135: =I135*1.01 -> 1.0530531 | K135: =J135*1.01 -> 1.0635836 | L135: =K135*1.01 -> 1.0742194 | M135: =L135*1.01 -> 1.0849616 | N135: =M135*1.01 -> 1.0958112 | O135: =N135*1.01 -> 1.1067693 | P135: =O135*1.01 -> 1.117837
C136: Risk-Free Rate | D136: =D137*0.99 -> 0.040512176 | E136: 44426.174 | F136: 43975.64 | G136: 43527.109 | H136: 43080.592 | I136: 42636.097 | J136: 42198.026 | K136: 41761.954 | L136: 41327.888 | M136: 40895.837 | N136: 40465.807 | O136: 40037.805 | P136: 39611.839
D137: =D138*0.99 -> 0.04092139 | E137: 44068.306 | F137: 43622.904 | G137: 43179.448 | H137: 42737.945 | I137: 42298.406 | J137: 41865.184 | K137: 41433.904 | L137: 41004.575 | M137: 40577.203 | N137: 40151.798 | O137: 39728.366 | P137: 39306.914
...

Sheet WS8 Work
B3: Income Statement
B4: Report Date | C4: 2020 | D4: 2021 | E4: 2022 | F4: 2023 | G4: =2024 -> 2024 | H4: 2025 | I4: 2026 | J4: 2027 | K4: 2028 | L4: 2029
B5: Sales | C5: =Financials!B4 -> 84432 | D5: =Financials!C4 -> 97204 | E5: =Financials!D4 -> 100034 | F5: =Financials!E4 -> 90745 | G5: =Financials!F4 -> 90894 | H5: ='Workshop #5'!P25 -> 94529.76 | I5: ='Workshop #5'!Q25 -> 98310.95 | J5: ='Workshop #5'!R25 -> 102243.39 | K5: ='Workshop #5'!S25 -> 106333.12 | L5: ='Workshop #5'!T25 -> 110586.45
B6: COGS | C6: =Financials!B5 -> 62649 | D6: =Financials!C5 -> 79772 | E6: =Financials!D5 -> 79954 | F6: =Financials!E5 -> 73039 | G6: =Financials!F5 -> 73836 | H6: ='Workshop #5'!P26 -> 76789.44 | I6: ='Workshop #5'!Q26 -> 79861.018 | J6: ='Workshop #5'!R26 -> 83055.458 | K6: ='Workshop #5'!S26 -> 86377.677 | L6: ='Workshop #5'!T26 -> 89832.784
B7: Gross Income | C7: =C5-C6 -> 21783 | D7: =D5-D6 -> 17432 | E7: =E5-E6 -> 20080 | F7: =F5-F6 -> 17706 | G7: =G5-G6 -> 17058 | H7: ='Workshop #5'!P27 -> 17740.32 | I7: ='Workshop #5'!Q27 -> 18449.933 | J7: ='Workshop #5'!R27 -> 19187.93 | K7: ='Workshop #5'!S27 -> 19955.447 | L7: ='Workshop #5'!T27 -> 20753.665
B8: Depreciation & Amortizaton | C8: =Financials!B8+Financials!B9 -> 2698 | D8: =Financials!C8+Financials!C9 -> 2953 | E8: =Financials!D8+Financials!D9 -> 3188 | F8: =Financials!E8+Financials!E9 -> 3366 | G8: =Financials!F8+Financials!F9 -> 3609 | H8: ='Workshop #5'!P28 -> 3753.36 | I8: ='Workshop #5'!Q28 -> 3903.4944 | J8: ='Workshop #5'!R28 -> 4059.6342 | K8: ='Workshop #5'!S28 -> 4222.0195 | L8: ='Workshop #5'!T28 -> 4390.9003
B9: SG&A | C9: =Financials!$F$11 -> 8684 | D9: =Financials!$F$11 -> 8684 | E9: =Financials!$F$11 -> 8684 | F9: =Financials!$F$11 -> 8684 | G9: =Financials!$F$11 -> 8684 | H9: ='Workshop #5'!P29 -> 9031.36 | I9: ='Workshop #5'!Q29 -> 9392.6144 | J9: ='Workshop #5'!R29 -> 9768.319 | K9: ='Workshop #5'!S29 -> 10159.052 | L9: ='Workshop #5'!T29 -> 10565.414
B10: Other Operating Expense | C10: =-Financials!B13 -> 0 | D10: =-Financials!C13 -> 0 | E10: =-Financials!D13 -> 0 | F10: =-Financials!E13 -> 0 | G10: =-Financials!F13 -> 311 | H10: ='Workshop #5'!P30 -> 323.44 | I10: ='Workshop #5'!Q30 -> 336.3776 | J10: ='Workshop #5'!R30 -> 349.8327 | K10: ='Workshop #5'!S30 -> 363.82601 | L10: ='Workshop #5'!T30 -> 378.37905
B11: Operating Income (EBIT) | C11: =C7-C9+C10 -> 13099 | D11: =D7-D9+D10 -> 8748 | E11: =E7-E9+E10 -> 11396 | F11: =F7-F9+F10 -> 9022 | G11: =G7-G9+G10 -> 8685 | H11: ='Workshop #5'!P31 -> 9032.4 | I11: ='Workshop #5'!Q31 -> 9393.696 | J11: ='Workshop #5'!R31 -> 9769.4438 | K11: ='Workshop #5'!S31 -> 10160.222 | L11: ='Workshop #5'!T31 -> 10566.63
B12: Other Income (Expense) | C12: =Financials!B17 -> -4978 | D12: =Financials!C17 -> 4590 | E12: =Financials!D17 -> 2729 | F12: =Financials!E17 -> 423 | G12: =Financials!F17 -> 17 | H12: ='Workshop #5'!P32 -> 17.68 | I12: ='Workshop #5'!Q32 -> 18.3872 | J12: ='Workshop #5'!R32 -> 19.122688 | K12: ='Workshop #5'!S32 -> 19.887596 | L12: ='Workshop #5'!T32 -> 20.683099
B13: Interest Expense | C13: =Financials!B18 -> 684 | D13: =Financials!C18 -> 683 | E13: =Financials!D18 -> 694 | F13: =Financials!E18 -> 775 | G13: =Financials!F18 -> 861 | H13: ='Workshop #5'!P33 -> 1250.2506 | I13: ='Workshop #5'!Q33 -> 590.47192 | J13: ='Workshop #5'!R33 -> 671.51927 | K13: ='Workshop #5'!S33 -> 763.09752 | L13: ='Workshop #5'!T33 -> 858.3389
B14: Unusual Expense | C14: =Financials!B21 -> 330 | D14: =Financials!C21 -> 419 | E14: =Financials!D21 -> 178 | F14: =Financials!E21 -> 446 | G14: =Financials!F21 -> 399 | H14: ='Workshop #5'!P34 -> 414.96 | I14: ='Workshop #5'!Q34 -> 431.5584 | J14: ='Workshop #5'!R34 -> 448.82074 | K14: ='Workshop #5'!S34 -> 466.77357 | L14: ='Workshop #5'!T34 -> 485.44451
B15: Earnings Before Tax | C15: =C11+C12-C13-C14 -> 7107 | D15: =D11+D12-D13-D14 -> 12236 | E15: =E11+E12-E13-E14 -> 13253 | F15: =F11+F12-F13-F14 -> 8224 | G15: =G11+G12-G13-G14 -> 7442 | H15: ='Workshop #5'!P35 -> 7384.8694 | I15: ='Workshop #5'!Q35 -> 8390.0529 | J15: ='Workshop #5'!R35 -> 8668.2265 | K15: ='Workshop #5'!S35 -> 8950.2381 | L15: ='Workshop #5'!T35 -> 9243.5302
B16: Income Tax | C16: =Financials!B28 -> 501 | D16: =Financials!C28 -> 3705 | E16: =Financials!D28 -> 3277 | F16: =Financials!E28 -> 1865 | G16: =Financials!F28 -> 1660 | H16: ='Workshop #5'!P36 -> 1726.4 | I16: ='Workshop #5'!Q36 -> 1795.456 | J16: ='Workshop #5'!R36 -> 1867.2742 | K16: ='Workshop #5'!S36 -> 1941.9652 | L16: ='Workshop #5'!T36 -> 2019.6438
B17: Net Income | C17: =C15-C16 -> 6606 | D17: =D15-D16 -> 8531 | E17: =E15-E16 -> 9976 | F17: =F15-F16 -> 6359 | G17: =G15-G16 -> 5782 | H17: ='Workshop #5'!P37 -> 5658.4694 | I17: ='Workshop #5'!Q37 -> 6594.5969 | J17: ='Workshop #5'!R37 -> 6800.9523 | K17: ='Workshop #5'!S37 -> 7008.2729 | L17: ='Workshop #5'!T37 -> 7223.8863
B20: Balance Sheet
B21: Report Date | C21: 2020 | D21: 2021 | E21: 2022 | F21: 2023 | G21: =2024 -> 2024 | H21: 2025 | I21: 2026 | J21: 2027 | K21: 2028 | L21: 2029
B22: Cash & ST Investments | C22: =Financials!B55 -> 6316 | D22: =Financials!C55 -> 10593 | E22: =Financials!D55 -> 7595 | F22: =Financials!E55 -> 6072 | G22: =Financials!F55 -> 6318 | H22: ='Workshop #5'!P45 -> 6570.72 | I22: ='Workshop #5'!Q45 -> 6833.5488 | J22: ='Workshop #5'!R45 -> 7106.8908 | K22: ='Workshop #5'!S45 -> 7391.1664 | L22: ='Workshop #5'!T45 -> 7686.813
B23: Receivables ST | C23: =Financials!B60 -> 11167 | D23: =Financials!C60 -> 12973 | E23: =Financials!D60 -> 13037 | F23: =Financials!E60 -> 11579 | G23: =Financials!F60 -> 11314 | H23: ='Workshop #5'!P46 -> 11766.56 | I23: ='Workshop #5'!Q46 -> 12237.222 | J23: ='Workshop #5'!R46 -> 12726.711 | K23: ='Workshop #5'!S46 -> 13235.78 | L23: ='Workshop #5'!T46 -> 13765.211
B24: Bad Debt | C24: =-Financials!B61 -> 138 | D24: =-Financials!C61 -> 128 | E24: =-Financials!D61 -> 146 | F24: =-Financials!E61 -> 126 | G24: =-Financials!F61 -> 136 | H24: ='Workshop #5'!P47 -> 141.44 | I24: ='Workshop #5'!Q47 -> 147.0976 | J24: ='Workshop #5'!R47 -> 152.9815 | K24: ='Workshop #5'!S47 -> 159.10076 | L24: ='Workshop #5'!T47 -> 165.46479
B25: Inventories | C25: =Financials!B63 -> 620 | D25: =Financials!C63 -> 717 | E25: =Financials!D63 -> 889 | F25: =Financials!E63 -> 935 | G25: =Financials!F63 -> 826 | H25: ='Workshop #5'!P48 -> 859.04 | I25: ='Workshop #5'!Q48 -> 893.4016 | J25: ='Workshop #5'!R48 -> 929.13766 | K25: ='Workshop #5'!S48 -> 966.30317 | L25: ='Workshop #5'!T48 -> 1004.9553
B26: Other Current Assets | C26: =Financials!B65 -> 2251 | D26: =Financials!C65 -> 779 | E26: =Financials!D65 -> 842 | F26: =Financials!E65 -> 953 | G26: =Financials!F65 -> 988 | H26: ='Workshop #5'!P49 -> 1027.52 | I26: ='Workshop #5'!Q49 -> 1068.6208 | J26: ='Workshop #5'!R49 -> 1111.3656 | K26: ='Workshop #5'!S49 -> 1155.8203 | L26: ='Workshop #5'!T49 -> 1202.0531
B27: Total Current Assets | C27: =C22+C23-C24+C25+C26 -> 20216 | D27: =D22+D23-D24+D25+D26 -> 24934 | E27: =E22+E23-E24+E25+E26 -> 22217 | F27: =F22+F23-F24+F25+F26 -> 19413 | G27: =G22+G23-G24+G25+G26 -> 19310 | H27: ='Workshop #5'!P50 -> 20082.4 | I27: ='Workshop #5'!Q50 -> 20885.696 | J27: ='Workshop #5'!R50 -> 21721.124 | K27: ='Workshop #5'!S50 -> 22589.969 | L27: ='Workshop #5'!T50 -> 23493.568
B28: Gross PP&E | C28: =Financials!B69 -> 65164 | D28: =Financials!C69 -> 68371 | E28: =Financials!D69 -> 71185 | F28: =Financials!E69 -> 75823 | G28: =Financials!F69 -> 77445 | H28: ='Workshop #5'!P51 -> 80542.8 | I28: ='Workshop #5'!Q51 -> 83764.512 | J28: ='Workshop #5'!R51 -> 87115.092 | K28: ='Workshop #5'!S51 -> 90599.696 | L28: ='Workshop #5'!T51 -> 94223.684
B29: Accumulated Depr | C29: =Financials!B77 -> 29837 | D29: =Financials!C77 -> 31334 | E29: =Financials!D77 -> 32711 | F29: =Financials!E77 -> 34570 | G29: =Financials!F77 -> 36117 | H29: ='Workshop #5'!P52 -> 37561.68 | I29: ='Workshop #5'!Q52 -> 39064.147 | J29: ='Workshop #5'!R52 -> 40626.713 | K29: ='Workshop #5'!S52 -> 42251.782 | L29: ='Workshop #5'!T52 -> 43941.853
B30: Net PP&E | C30: =C28-C29 -> 35327 | D30: =D28-D29 -> 37037 | E30: =E28-E29 -> 38474 | F30: =F28-F29 -> 41253 | G30: =G28-G29 -> 41328 | H30: ='Workshop #5'!P53 -> 42981.12 | I30: ='Workshop #5'!Q53 -> 44700.365 | J30: ='Workshop #5'!R53 -> 46488.379 | K30: ='Workshop #5'!S53 -> 48347.915 | L30: ='Workshop #5'!T53 -> 50281.831
B31: Intangible Assets | C31: =Financials!B81 -> 5641 | D31: =Financials!C81 -> 6178 | E31: =Financials!D81 -> 7019 | F31: =Financials!E81 -> 8177 | G31: =Financials!F81 -> 7364 | H31: ='Workshop #5'!P54 -> 7658.56 | I31: ='Workshop #5'!Q54 -> 7964.9024 | J31: ='Workshop #5'!R54 -> 8283.4985 | K31: ='Workshop #5'!S54 -> 8614.8384 | L31: ='Workshop #5'!T54 -> 8959.432
B32: Other Assets | C32: =Financials!B85 -> 672 | D32: =Financials!C85 -> 1054 | E32: =Financials!D85 -> 2720 | F32: =Financials!E85 -> 1464 | G32: =Financials!F85 -> 1457 | H32: ='Workshop #5'!P55 -> 1515.28 | I32: ='Workshop #5'!Q55 -> 1575.8912 | J32: ='Workshop #5'!R55 -> 1638.9268 | K32: ='Workshop #5'!S55 -> 1704.4839 | L32: ='Workshop #5'!T55 -> 1772.6633
B33: Long-Term Investments | C33: =Financials!B78 -> 25 | D33: =Financials!C78 -> 26 | E33: =Financials!D78 -> 555 | F33: =Financials!E78 -> 424 | G33: =Financials!F78 -> 499 | H33: ='Workshop #5'!P56 -> 518.96 | I33: ='Workshop #5'!Q56 -> 539.7184 | J33: ='Workshop #5'!R56 -> 561.30714 | K33: ='Workshop #5'!S56 -> 583.75942 | L33: ='Workshop #5'!T56 -> 607.1098
B34: Deferred Tax Assets | C34: =Financials!B84 -> 527 | D34: =Financials!C84 -> 176 | E34: =Financials!D84 -> 139 | F34: =Financials!E84 -> 126 | G34: =Financials!F84 -> 112 | H34: ='Workshop #5'!P57 -> 116.48 | I34: ='Workshop #5'!Q57 -> 121.1392 | J34: ='Workshop #5'!R57 -> 125.98477 | K34: ='Workshop #5'!S57 -> 131.02416 | L34: ='Workshop #5'!T57 -> 136.26513
B35: Total Assets | C35: =SUM(C27,C30:C34) -> 62408 | D35: =SUM(D27,D30:D34) -> 69405 | E35: =SUM(E27,E30:E34) -> 71124 | F35: =SUM(F27,F30:F34) -> 70857 | G35: =SUM(G27,G30:G34) -> 70070 | H35: ='Workshop #5'!P58 -> 72872.8 | I35: ='Workshop #5'!Q58 -> 75787.712 | J35: ='Workshop #5'!R58 -> 78819.22 | K35: ='Workshop #5'!S58 -> 81971.989 | L35: ='Workshop #5'!T58 -> 85250.869
B36: Accounts Payable | C36: =Financials!B90 -> 6455 | D36: =Financials!C90 -> 7523 | E36: =Financials!D90 -> 7512 | F36: =Financials!E90 -> 6340 | G36: =Financials!F90 -> 6302 | H36: ='Workshop #5'!P59 -> 6554.08 | I36: ='Workshop #5'!Q59 -> 6816.2432 | J36: ='Workshop #5'!R59 -> 7088.8929 | K36: ='Workshop #5'!S59 -> 7372.4486 | L36: ='Workshop #5'!T59 -> 7667.3466
B37: ST Debt | C37: =Financials!B89 -> 3183 | D37: =Financials!C89 -> 2711 | E37: =Financials!D89 -> 2962 | F37: =Financials!E89 -> 4057 | G37: =Financials!F89 -> 2571 | H37: ='Workshop #5'!P60 -> 2571 | I37: ='Workshop #5'!Q60 -> 2571 | J37: ='Workshop #5'!R60 -> 2571 | K37: ='Workshop #5'!S60 -> 2571 | L37: ='Workshop #5'!T60 -> 2571
B38: Other Current Liabilities | C38: =Financials!B91 -> 7378 | D38: =Financials!C91 -> 7335 | E38: =Financials!D91 -> 7666 | F38: =Financials!E91 -> 7279 | G38: =Financials!F91 -> 7568 | H38: ='Workshop #5'!P61 -> 7568 | I38: ='Workshop #5'!Q61 -> 7568 | J38: ='Workshop #5'!R61 -> 7568 | K38: ='Workshop #5'!S61 -> 7568 | L38: ='Workshop #5'!T61 -> 7568
B39: Total Current Liabilities | C39: =SUM(C36:C38) -> 17016 | D39: =SUM(D36:D38) -> 17569 | E39: =SUM(E36:E38) -> 18140 | F39: =SUM(F36:F38) -> 17676 | G39: =SUM(G36:G38) -> 16441 | H39: ='Workshop #5'!P62 -> 16693.08 | I39: ='Workshop #5'!Q62 -> 16955.243 | J39: ='Workshop #5'!R62 -> 17227.893 | K39: ='Workshop #5'!S62 -> 17511.449 | L39: ='Workshop #5'!T62 -> 17806.347
B40: LT Debt | C40: =Financials!B95 -> 24571 | D40: =Financials!C95 -> 22817 | E40: =Financials!D95 -> 20559 | F40: =Financials!E95 -> 22672 | G40: =Financials!F95 -> 23081 | H40: ='Workshop #5'!P63 -> 9544 | I40: ='Workshop #5'!Q63 -> 11206.888 | J40: ='Workshop #5'!R63 -> 13085.844 | K40: ='Workshop #5'!S63 -> 15039.957 | L40: ='Workshop #5'!T63 -> 17072.236
B41: Provisions for Risk & Charges | C41: =Financials!B98 -> 16654 | D41: =Financials!C98 -> 8877 | E41: =Financials!D98 -> 5628 | F41: =Financials!E98 -> 6972 | G41: =Financials!F98 -> 7663 | H41: ='Workshop #5'!P64 -> 23081 | I41: ='Workshop #5'!Q64 -> 23081 | J41: ='Workshop #5'!R64 -> 23081 | K41: ='Workshop #5'!S64 -> 23081 | L41: ='Workshop #5'!T64 -> 23081
B42: Deffered Tax Liabilities | C42: =Financials!B99 -> 488 | D42: =Financials!C99 -> 3125 | E42: =Financials!D99 -> 4302 | F42: =Financials!E99 -> 3772 | G42: =Financials!F99 -> 3595 | H42: ='Workshop #5'!P65 -> 3595 | I42: ='Workshop #5'!Q65 -> 3888.352 | J42: ='Workshop #5'!R65 -> 4043.8861 | K42: ='Workshop #5'!S65 -> 4205.6415 | L42: ='Workshop #5'!T65 -> 4373.8672
B43: Other Liabilities | C43: =Financials!B100 -> 3010 | D43: =Financials!C100 -> 2748 | E43: =Financials!D100 -> 2692 | F43: =Financials!E100 -> 2451 | G43: =Financials!F100 -> 2547 | H43: ='Workshop #5'!P66 -> 2547 | I43: ='Workshop #5'!Q66 -> 2547 | J43: ='Workshop #5'!R66 -> 2547 | K43: ='Workshop #5'!S66 -> 2547 | L43: ='Workshop #5'!T66 -> 2547
B44: Total Liabilities | C44: =SUM(C39:C43) -> 61739 | D44: =SUM(D39:D43) -> 55136 | E44: =SUM(E39:E43) -> 51321 | F44: =SUM(F39:F43) -> 53543 | G44: =SUM(G39:G43) -> 53327 | H44: ='Workshop #5'!P67 -> 55460.08 | I44: ='Workshop #5'!Q67 -> 57678.483 | J44: ='Workshop #5'!R67 -> 59985.623 | K44: ='Workshop #5'!S67 -> 62385.047 | L44: ='Workshop #5'!T67 -> 64880.449

Sheet WS6 Work
B4: UPS 10-Year Historical Prices | F4: S&P500 10-Year Historical Prices | J4: 60 Month Rolling Beta
B6: Date | C6: Price | F6: Date | G6: Price | H6: Return | J6: Date | K6: Beta
B7: 46052 | C7: 106.22 | D7: UPS | F7: 46052 | G7: 6939.03 | H7: S&P500 | J7: 46052 | K7: =SLOPE(D7:D67,H7:H67) -> 1.1110203
B8: 46022 | C8: 99.19 | D8: =(C8-C7)/C7 -> -0.066183393 | F8: 46022 | G8: 6845.5047 | H8: =(G8-G7)/G7 -> -0.013478151 | J8: 46022 | K8: =SLOPE(D8:D68,H8:H68) -> 1.1207493
B9: 45989 | C9: 95.79 | D9: =(C9-C8)/C8 -> -0.034277649 | F9: 45989 | G9: 6849.0874 | H9: =(G9-G8)/G8 -> 0.00052336042 | J9: 45989 | K9: =SLOPE(D9:D69,H9:H69) -> 1.1100819
B10: 45961 | C10: 96.42 | D10: =(C10-C9)/C9 -> 0.0065768869 | F10: 45961 | G10: 6840.1987 | H10: =(G10-G9)/G9 -> -0.0012977833 | J10: 45961 | K10: =SLOPE(D10:D70,H10:H70) -> 1.1129741
B11: 45930 | C11: 83.53 | D11: =(C11-C10)/C10 -> -0.13368596 | F11: 45930 | G11: 6688.459 | H11: =(G11-G10)/G10 -> -0.022183523 | J11: 45930 | K11: =SLOPE(D11:D71,H11:H71) -> 1.1158557
B12: 45898 | C12: 87.44 | D12: =(C12-C11)/C11 -> 0.04680953 | F12: 45898 | G12: 6460.2627 | H12: =(G12-G11)/G11 -> -0.034117929 | J12: 45898 | K12: =SLOPE(D12:D72,H12:H72) -> 1.0671493
B13: 45869 | C13: 86.16 | D13: =(C13-C12)/C12 -> -0.014638609 | F13: 45869 | G13: 6339.3946 | H13: =(G13-G12)/G12 -> -0.018709471 | J13: 45869 | K13: =SLOPE(D13:D73,H13:H73) -> 1.1138382
B14: 45838 | C14: 100.94 | D14: =(C14-C13)/C13 -> 0.17154132 | F14: 45838 | G14: 6204.954 | H14: =(G14-G13)/G13 -> -0.021207169 | J14: 45838 | K14: =SLOPE(D14:D74,H14:H74) -> 1.1725401
B15: 45807 | C15: 97.54 | D15: =(C15-C14)/C14 -> -0.033683376 | F15: 45807 | G15: 5911.6867 | H15: =(G15-G14)/G14 -> -0.047263401 | J15: 45807 | K15: =SLOPE(D15:D75,H15:H75) -> 1.1930128
B16: 45777 | C16: 95.3 | D16: =(C16-C15)/C15 -> -0.022964937 | F16: 45777 | G16: 5569.0647 | H16: =(G16-G15)/G15 -> -0.057956733 | J16: 45777 | K16: =SLOPE(D16:D76,H16:H76) -> 1.1987407
B17: 45747 | C17: 109.99 | D17: =(C17-C16)/C16 -> 0.15414481 | F17: 45747 | G17: 5611.8526 | H17: =(G17-G16)/G16 -> 0.0076831451 | J17: 45747 | K17: =SLOPE(D17:D77,H17:H77) -> 1.1307935
B18: 45716 | C18: 119.03 | D18: =(C18-C17)/C17 -> 0.08218929 | F18: 45716 | G18: 5954.5048 | H18: =(G18-G17)/G17 -> 0.061058664 | J18: 45716 | K18: =SLOPE(D18:D78,H18:H78) -> 0.91853452
B19: 45688 | C19: 114.23 | D19: =(C19-C18)/C18 -> -0.040325968 | F19: 45688 | G19: 6040.5259 | H19: =(G19-G18)/G18 -> 0.014446391 | J19: 45688 | K19: =SLOPE(D19:D79,H19:H79) -> 0.94216847
... B67: 44225 | C67: 155 | D67: =(C67-C66)/C66 -> -0.017930685 | F67: 44225 | G67: 3714.2427 | H67: =(G67-G66)/G66 -> -0.025427251 | J67: 44225 | K67: =SLOPE(D67:D127,H67:H127) -> 1.0079415
B68: 44196 | C68: 168.4 | D68: =(C68-C67)/C67 -> 0.086451613 | F68: 44196 | G68: 3756.0715 | H68: =(G68-G67)/G67 -> 0.011261725 | J68: 44196 | K68: =SLOPE(D68:D127,H68:H127) -> 1.0083852
B69: 44165 | C69: 171.07 | D69: =(C69-C68)/C68 -> 0.015855107 | F69: 44165 | G69: 3621.6334 | H69: =(G69-G68)/G68 -> -0.035792194 | J69: 44165 | K69: =SLOPE(D69:D128,H69:H128) -> 0.99493508
B70: 44134 | C70: 157.11 | D70: =(C70-C69)/C69 -> -0.081604022 | F70: 44134 | G70: 3269.9591 | H70: =(G70-G69)/G69 -> -0.097103793 | J70: 44134 | K70: =SLOPE(D70:D129,H70:H129) -> 1.0061771
B71: 44104 | C71: 166.63 | D71: =(C71-C70)/C70 -> 0.060594488 | F71: 44104 | G71: 3362.999 | H71: =(G71-G70)/G70 -> 0.028452925 | J71: 44104 | K71: =SLOPE(D71:D130,H71:H130) -> 1.0178796
B72: 44074 | C72: 163.62 | D72: =(C72-C71)/C71 -> -0.018063974 | F72: 44074 | G72: 3500.3085 | H72: =(G72-G71)/G71 -> 0.04082949 | J72: 44074 | K72: =SLOPE(D72:D131,H72:H131) -> 1.007214
B73: 44043 | C73: 142.76 | D73: =(C73-C72)/C72 -> -0.12749053 | F73: 44043 | G73: 3271.1249 | H73: =(G73-G72)/G72 -> -0.065475268 | J73: 44043 | K73: =SLOPE(D73:D132,H73:H132) -> 1.0378556
B74: 44012 | C74: 111.18 | D74: =(C74-C73)/C73 -> -0.22121042 | F74: 44012 | G74: 3100.2851 | H74: =(G74-G73)/G73 -> -0.052226606 | J74: 44012 | K74: =SLOPE(D74:D133,H74:H133) -> 0.95149402
B75: 43980 | C75: 99.71 | D75: =(C75-C74)/C74 -> -0.10316604 | F75: 43980 | G75: 3044.3052 | H75: =(G75-G74)/G74 -> -0.018056395 | J75: 43980 | K75: =SLOPE(D75:D134,H75:H134) -> 0.80860655
B76: 43951 | C76: 94.66 | D76: =(C76-C75)/C75 -> -0.050646876 | F76: 43951 | G76: 2912.4305 | H76: =(G76-G75)/G75 -> -0.043318466 | J76: 43951 | K76: =SLOPE(D76:D135,H76:H135) -> 0.80373047
B77: 43921 | C77: 93.42 | D77: =(C77-C76)/C76 -> -0.013099514 | F77: 43921 | G77: 2584.5908 | H77: =(G77-G76)/G76 -> -0.11256569 | J77: 43921 | K77: =SLOPE(D77:D136,H77:H136) -> 0.74931892
B78: 43889 | C78: 90.49 | D78: =(C78-C77)/C77 -> -0.031363734 | F78: 43889 | G78: 2954.2237 | H78: =(G78-G77)/G77 -> 0.1430141 | J78: 43889 | K78: =SLOPE(D78:D137,H78:H137) -> 0.78872552
B79: 43861 | C79: 103.52 | D79: =(C79-C78)/C78 -> 0.14399381 | F79: 43861 | G79: 3225.5163 | H79: =(G79-G78)/G78 -> 0.091832123 | J79: 43861 | K79: =SLOPE(D79:D138,H79:H138) -> 0.97455802
... B127: 42398 | C127: 93.2 | D127: =(C127-C126)/C126 -> -0.034697048 | F127: 42398 | G127: 1940.2397 | H127: =(G127-G126)/G126 -> 0.004147176 | J127: 42398 | K127: =SLOPE(D127:D186,H127:H186) -> 0.3197099
B130: S&P 500 5-Year Historical Prices | F130: FDX 5-Year Historical Prices | J130: DHL 5-Year Historical Prices | N130: EXPD 5-Year Historical Prices | R130: ODFL 5-Year Historical Prices | V130: TFII 5-Year Historical Prices
B131: Date | C131: Price | D131: Return | F131: Date | G131: Price | H131: Return | J131: Date | K131: Price | L131: Return | N131: Date | O131: Price | P131: Return | R131: Date | S131: Price | T131: Return | V131: Date | W131: Price | X131: Return
B132: 44225 | C132: 3714.2427 | D132: S&P500 | F132: 44225 | G132: 235.34 | H132: FDX | J132: 44225 | K132: 49.580067 | L132: DHL | N132: 44225 | O132: 89.52 | P132: EXPD | R132: 44253 | S132: 107.385 | T132: ODFL | V132: 44225 | W132: 66.491844 | X132: TFII
B133: 44253 | C133: 3811.1497 | D133: =(C133-C132)/C132 -> 0.026090664 | F133: 44253 | G133: 254.5 | H133: =(G133-G132)/G132 -> 0.081414124 | J133: 44253 | K133: 49.838627 | L133: =(K133-K132)/K132 -> 0.005214999 | N133: 44253 | O133: 91.84 | P133: =(O133-O132)/O132 -> 0.025915996 | R133: 44286 | S133: 120.205 | T133: =(S133-S132)/S132 -> 0.11938353 | V133: 44253 | W133: 70.213264 | X133: =(W133-W132)/W132 -> 0.055968067
B134: 44286 | C134: 3972.8922 | D134: =(C134-C133)/C133 -> 0.042439282 | F134: 44286 | G134: 284.04 | H134: =(G134-G133)/G133 -> 0.11607073 | J134: 44286 | K134: 54.910015 | L134: =(K134-K133)/K133 -> 0.10175617 | N134: 44286 | O134: 107.69 | P134: =(O134-O133)/O133 -> 0.17258275 | R134: 44316 | S134: 128.905 | T134: =(S134-S133)/S133 -> 0.072376357 | V134: 44286 | W134: 74.94927 | X134: =(W134-W133)/W133 -> 0.067451728
